Time slot   0
ld_routine
Time slot   1
	Loaded a process at input/proc/p1, PID: 1, NICENESS: 0
Time slot   2
	CPU 0: Dispatched process  1 (niceness: 0, weight: 1024.000000, vruntime: 0.000000, time_slice: 3)
	Loaded a process at input/proc/p2, PID: 2, NICENESS: -5
Time slot   3
	Loaded a process at input/proc/p3, PID: 3, NICENESS: 5
Time slot   4
	Loaded a process at input/proc/p4, PID: 4, NICENESS: 10
Time slot   5
	CPU 0: Put process  1 to run queue (niceness: 0, vruntime: 2.929688)
	CPU 0: Dispatched process  2 (niceness: -5, weight: 1448.154688, vruntime: 0.000000, time_slice: 1)
Time slot   6
	CPU 0: Put process  2 to run queue (niceness: -5, vruntime: 0.690534)
	CPU 0: Dispatched process  3 (niceness: 5, weight: 724.077344, vruntime: 0.000000, time_slice: 1)
Time slot   7
	CPU 0: Put process  3 to run queue (niceness: 5, vruntime: 1.381068)
	CPU 0: Dispatched process  4 (niceness: 10, weight: 512.000000, vruntime: 0.000000, time_slice: 1)
Time slot   8
	CPU 0: Put process  4 to run queue (niceness: 10, vruntime: 1.953125)
	CPU 0: Dispatched process  2 (niceness: -5, weight: 1448.154688, vruntime: 0.690534, time_slice: 1)
Time slot   9
	CPU 0: Put process  2 to run queue (niceness: -5, vruntime: 1.381068)
	CPU 0: Dispatched process  3 (niceness: 5, weight: 724.077344, vruntime: 1.381068, time_slice: 1)
Time slot  10
	CPU 0: Put process  3 to run queue (niceness: 5, vruntime: 2.762136)
	CPU 0: Dispatched process  2 (niceness: -5, weight: 1448.154688, vruntime: 1.381068, time_slice: 1)
Time slot  11
	CPU 0: Put process  2 to run queue (niceness: -5, vruntime: 2.071602)
	CPU 0: Dispatched process  4 (niceness: 10, weight: 512.000000, vruntime: 1.953125, time_slice: 1)
Time slot  12
	CPU 0: Put process  4 to run queue (niceness: 10, vruntime: 3.906250)
	CPU 0: Dispatched process  2 (niceness: -5, weight: 1448.154688, vruntime: 2.071602, time_slice: 1)
Time slot  13
	CPU 0: Processed  2 has finished (niceness: -5, vruntime: 2.071602)
	CPU 0: Dispatched process  3 (niceness: 5, weight: 724.077344, vruntime: 2.762136, time_slice: 1)
Time slot  14
	CPU 0: Put process  3 to run queue (niceness: 5, vruntime: 4.143204)
	CPU 0: Dispatched process  1 (niceness: 0, weight: 1024.000000, vruntime: 2.929688, time_slice: 1)
Time slot  15
	CPU 0: Put process  1 to run queue (niceness: 0, vruntime: 3.906250)
	CPU 0: Dispatched process  4 (niceness: 10, weight: 512.000000, vruntime: 3.906250, time_slice: 1)
Time slot  16
	CPU 0: Put process  4 to run queue (niceness: 10, vruntime: 5.859375)
	CPU 0: Dispatched process  1 (niceness: 0, weight: 1024.000000, vruntime: 3.906250, time_slice: 1)
Time slot  17
	CPU 0: Put process  1 to run queue (niceness: 0, vruntime: 4.882812)
	CPU 0: Dispatched process  3 (niceness: 5, weight: 724.077344, vruntime: 4.143204, time_slice: 1)
Time slot  18
	CPU 0: Put process  3 to run queue (niceness: 5, vruntime: 5.524272)
	CPU 0: Dispatched process  1 (niceness: 0, weight: 1024.000000, vruntime: 4.882812, time_slice: 1)
Time slot  19
	CPU 0: Put process  1 to run queue (niceness: 0, vruntime: 5.859375)
	CPU 0: Dispatched process  3 (niceness: 5, weight: 724.077344, vruntime: 5.524272, time_slice: 1)
Time slot  20
	CPU 0: Put process  3 to run queue (niceness: 5, vruntime: 6.905340)
	CPU 0: Dispatched process  4 (niceness: 10, weight: 512.000000, vruntime: 5.859375, time_slice: 1)
Time slot  21
	CPU 0: Put process  4 to run queue (niceness: 10, vruntime: 7.812500)
	CPU 0: Dispatched process  1 (niceness: 0, weight: 1024.000000, vruntime: 5.859375, time_slice: 1)
Time slot  22
	CPU 0: Put process  1 to run queue (niceness: 0, vruntime: 6.835938)
	CPU 0: Dispatched process  1 (niceness: 0, weight: 1024.000000, vruntime: 6.835938, time_slice: 1)
Time slot  23
	CPU 0: Processed  1 has finished (niceness: 0, vruntime: 6.835938)
	CPU 0: Dispatched process  3 (niceness: 5, weight: 724.077344, vruntime: 6.905340, time_slice: 2)
Time slot  24
Time slot  25
	CPU 0: Put process  3 to run queue (niceness: 5, vruntime: 9.667476)
	CPU 0: Dispatched process  4 (niceness: 10, weight: 512.000000, vruntime: 7.812500, time_slice: 1)
Time slot  26
	CPU 0: Processed  4 has finished (niceness: 10, vruntime: 7.812500)
	CPU 0: Dispatched process  3 (niceness: 5, weight: 724.077344, vruntime: 9.667476, time_slice: 3)
Time slot  27
Time slot  28
	CPU 0: Processed  3 has finished (niceness: 5, vruntime: 9.667476)
	CPU 0 stopped
