Time slot   0
ld_routine
Time slot   1
	Loaded a process at input/proc/p1, PID: 1, NICENESS: 0
Time slot   2
	CPU 0: Dispatched process  1 (niceness: 0, weight: 1024.000000, vruntime: 0.000000, time_slice: 3)
	Loaded a process at input/proc/p2, PID: 2, NICENESS: -5
Time slot   3
Time slot   4
Time slot   5
	CPU 0: Put process  1 to run queue (niceness: 0, vruntime: 2.929688)
	CPU 0: Dispatched process  2 (niceness: -5, weight: 1448.154688, vruntime: 0.000000, time_slice: 2)
Time slot   6
Time slot   7
	CPU 0: Put process  2 to run queue (niceness: -5, vruntime: 1.381068)
	CPU 0: Dispatched process  2 (niceness: -5, weight: 1448.154688, vruntime: 1.381068, time_slice: 2)
Time slot   8
Time slot   9
	CPU 0: Put process  2 to run queue (niceness: -5, vruntime: 2.762136)
	CPU 0: Dispatched process  2 (niceness: -5, weight: 1448.154688, vruntime: 2.762136, time_slice: 2)
Time slot  10
Time slot  11
	CPU 0: Put process  2 to run queue (niceness: -5, vruntime: 4.143204)
	CPU 0: Dispatched process  1 (niceness: 0, weight: 1024.000000, vruntime: 2.929688, time_slice: 1)
Time slot  12
	CPU 0: Put process  1 to run queue (niceness: 0, vruntime: 3.906250)
	CPU 0: Dispatched process  1 (niceness: 0, weight: 1024.000000, vruntime: 3.906250, time_slice: 1)
	Loaded a process at input/proc/p3, PID: 3, NICENESS: 5
Time slot  13
	CPU 0: Put process  1 to run queue (niceness: 0, vruntime: 4.882812)
	CPU 0: Dispatched process  2 (niceness: -5, weight: 1448.154688, vruntime: 4.143204, time_slice: 1)
Time slot  14
	CPU 0: Put process  2 to run queue (niceness: -5, vruntime: 4.833738)
	CPU 0: Dispatched process  3 (niceness: 5, weight: 724.077344, vruntime: 4.143204, time_slice: 1)
Time slot  15
	CPU 0: Put process  3 to run queue (niceness: 5, vruntime: 5.524272)
	CPU 0: Dispatched process  2 (niceness: -5, weight: 1448.154688, vruntime: 4.833738, time_slice: 1)
Time slot  16
	CPU 0: Put process  2 to run queue (niceness: -5, vruntime: 5.524272)
	CPU 0: Dispatched process  1 (niceness: 0, weight: 1024.000000, vruntime: 4.882812, time_slice: 1)
Time slot  17
	CPU 0: Put process  1 to run queue (niceness: 0, vruntime: 5.859375)
	CPU 0: Dispatched process  3 (niceness: 5, weight: 724.077344, vruntime: 5.524272, time_slice: 1)
	Loaded a process at input/proc/p4, PID: 4, NICENESS: 10
Time slot  18
	CPU 0: Put process  3 to run queue (niceness: 5, vruntime: 6.905340)
	CPU 0: Dispatched process  2 (niceness: -5, weight: 1448.154688, vruntime: 5.524272, time_slice: 1)
Time slot  19
	CPU 0: Put process  2 to run queue (niceness: -5, vruntime: 6.214806)
	CPU 0: Dispatched process  4 (niceness: 10, weight: 512.000000, vruntime: 5.524272, time_slice: 1)
Time slot  20
	CPU 0: Put process  4 to run queue (niceness: 10, vruntime: 7.477397)
	CPU 0: Dispatched process  1 (niceness: 0, weight: 1024.000000, vruntime: 5.859375, time_slice: 1)
Time slot  21
	CPU 0: Put process  1 to run queue (niceness: 0, vruntime: 6.835938)
	CPU 0: Dispatched process  2 (niceness: -5, weight: 1448.154688, vruntime: 6.214806, time_slice: 1)
Time slot  22
	CPU 0: Put process  2 to run queue (niceness: -5, vruntime: 6.905340)
	CPU 0: Dispatched process  1 (niceness: 0, weight: 1024.000000, vruntime: 6.835938, time_slice: 1)
Time slot  23
	CPU 0: Processed  1 has finished (niceness: 0, vruntime: 6.835938)
	      Waiting time: 14, Turnaround time: 22, CPU burst time: 8
	CPU 0: Dispatched process  3 (niceness: 5, weight: 724.077344, vruntime: 6.905340, time_slice: 1)
Time slot  24
	CPU 0: Put process  3 to run queue (niceness: 5, vruntime: 8.286408)
	CPU 0: Dispatched process  2 (niceness: -5, weight: 1448.154688, vruntime: 6.905340, time_slice: 2)
Time slot  25
Time slot  26
	CPU 0: Processed  2 has finished (niceness: -5, vruntime: 6.905340)
	      Waiting time: 12, Turnaround time: 24, CPU burst time: 12
	CPU 0: Dispatched process  4 (niceness: 10, weight: 512.000000, vruntime: 7.477397, time_slice: 1)
Time slot  27
	CPU 0: Put process  4 to run queue (niceness: 10, vruntime: 9.430522)
	CPU 0: Dispatched process  3 (niceness: 5, weight: 724.077344, vruntime: 8.286408, time_slice: 2)
Time slot  28
Time slot  29
	CPU 0: Put process  3 to run queue (niceness: 5, vruntime: 11.048543)
	CPU 0: Dispatched process  4 (niceness: 10, weight: 512.000000, vruntime: 9.430522, time_slice: 1)
Time slot  30
	CPU 0: Put process  4 to run queue (niceness: 10, vruntime: 11.383647)
	CPU 0: Dispatched process  3 (niceness: 5, weight: 724.077344, vruntime: 11.048543, time_slice: 2)
Time slot  31
Time slot  32
	CPU 0: Put process  3 to run queue (niceness: 5, vruntime: 13.810679)
	CPU 0: Dispatched process  4 (niceness: 10, weight: 512.000000, vruntime: 11.383647, time_slice: 1)
Time slot  33
	CPU 0: Put process  4 to run queue (niceness: 10, vruntime: 13.336772)
	CPU 0: Dispatched process  4 (niceness: 10, weight: 512.000000, vruntime: 13.336772, time_slice: 1)
Time slot  34
	CPU 0: Processed  4 has finished (niceness: 10, vruntime: 13.336772)
	      Waiting time: 12, Turnaround time: 17, CPU burst time: 5
	CPU 0: Dispatched process  3 (niceness: 5, weight: 724.077344, vruntime: 13.810679, time_slice: 3)
Time slot  35
Time slot  36
	CPU 0: Processed  3 has finished (niceness: 5, vruntime: 13.810679)
	      Waiting time: 15, Turnaround time: 24, CPU burst time: 9
	CPU 0 stopped

=== Scheduling Statistics ===
Scheduler: CFS (Completely Fair Scheduler)
Number of processes completed: 4
Average waiting time: 13.25 time units
Average turnaround time: 21.75 time units
============================
