Time slot   0
ld_routine
Time slot   1
	Loaded a process at input/proc/p6, PID: 1, NICENESS: 5
Time slot   2
	CPU 0: Dispatched process  1 (niceness: 5, weight: 724.077344, vruntime: 0.000000, time_slice: 3)
	Loaded a process at input/proc/p5, PID: 2, NICENESS: -10
Time slot   3
Time slot   4
	Loaded a process at input/proc/p7, PID: 3, NICENESS: 0
Time slot   5
	CPU 0: Put process  1 to run queue (niceness: 5, vruntime: 4.143204)
	CPU 0: Dispatched process  2 (niceness: -10, weight: 2048.000000, vruntime: 0.000000, time_slice: 2)
Time slot   6
Time slot   7
	CPU 0: Put process  2 to run queue (niceness: -10, vruntime: 0.976562)
	CPU 0: Dispatched process  3 (niceness: 0, weight: 1024.000000, vruntime: 0.000000, time_slice: 1)
Time slot   8
	CPU 0: Put process  3 to run queue (niceness: 0, vruntime: 0.976562)
	CPU 0: Dispatched process  2 (niceness: -10, weight: 2048.000000, vruntime: 0.976562, time_slice: 2)
Time slot   9
Time slot  10
	CPU 0: Put process  2 to run queue (niceness: -10, vruntime: 1.953125)
	CPU 0: Dispatched process  3 (niceness: 0, weight: 1024.000000, vruntime: 0.976562, time_slice: 1)
Time slot  11
	CPU 0: Put process  3 to run queue (niceness: 0, vruntime: 1.953125)
	CPU 0: Dispatched process  2 (niceness: -10, weight: 2048.000000, vruntime: 1.953125, time_slice: 2)
Time slot  12
Time slot  13
	CPU 0: Put process  2 to run queue (niceness: -10, vruntime: 2.929688)
	CPU 0: Dispatched process  3 (niceness: 0, weight: 1024.000000, vruntime: 1.953125, time_slice: 1)
Time slot  14
	CPU 0: Put process  3 to run queue (niceness: 0, vruntime: 2.929688)
	CPU 0: Dispatched process  2 (niceness: -10, weight: 2048.000000, vruntime: 2.929688, time_slice: 2)
Time slot  15
Time slot  16
	CPU 0: Put process  2 to run queue (niceness: -10, vruntime: 3.906250)
	CPU 0: Dispatched process  3 (niceness: 0, weight: 1024.000000, vruntime: 2.929688, time_slice: 1)
Time slot  17
	CPU 0: Put process  3 to run queue (niceness: 0, vruntime: 3.906250)
	CPU 0: Dispatched process  2 (niceness: -10, weight: 2048.000000, vruntime: 3.906250, time_slice: 2)
Time slot  18
Time slot  19
	CPU 0: Put process  2 to run queue (niceness: -10, vruntime: 4.882812)
	CPU 0: Dispatched process  3 (niceness: 0, weight: 1024.000000, vruntime: 3.906250, time_slice: 1)
Time slot  20
	CPU 0: Put process  3 to run queue (niceness: 0, vruntime: 4.882812)
	CPU 0: Dispatched process  1 (niceness: 5, weight: 724.077344, vruntime: 4.143204, time_slice: 1)
Time slot  21
	CPU 0: Put process  1 to run queue (niceness: 5, vruntime: 5.524272)
	CPU 0: Dispatched process  2 (niceness: -10, weight: 2048.000000, vruntime: 4.882812, time_slice: 2)
Time slot  22
Time slot  23
	CPU 0: Put process  2 to run queue (niceness: -10, vruntime: 5.859375)
	CPU 0: Dispatched process  3 (niceness: 0, weight: 1024.000000, vruntime: 4.882812, time_slice: 1)
Time slot  24
	CPU 0: Put process  3 to run queue (niceness: 0, vruntime: 5.859375)
	CPU 0: Dispatched process  1 (niceness: 5, weight: 724.077344, vruntime: 5.524272, time_slice: 1)
Time slot  25
	CPU 0: Processed  1 has finished (niceness: 5, vruntime: 5.524272)
	CPU 0: Dispatched process  2 (niceness: -10, weight: 2048.000000, vruntime: 5.859375, time_slice: 2)
Time slot  26
Time slot  27
	CPU 0: Put process  2 to run queue (niceness: -10, vruntime: 6.835938)
	CPU 0: Dispatched process  3 (niceness: 0, weight: 1024.000000, vruntime: 5.859375, time_slice: 1)
Time slot  28
	CPU 0: Put process  3 to run queue (niceness: 0, vruntime: 6.835938)
	CPU 0: Dispatched process  2 (niceness: -10, weight: 2048.000000, vruntime: 6.835938, time_slice: 2)
Time slot  29
	CPU 0: Processed  2 has finished (niceness: -10, vruntime: 6.835938)
	CPU 0: Dispatched process  3 (niceness: 0, weight: 1024.000000, vruntime: 6.835938, time_slice: 3)
Time slot  30
Time slot  31
Time slot  32
	CPU 0: Processed  3 has finished (niceness: 0, vruntime: 6.835938)
	CPU 0 stopped
