Time slot   0
ld_routine
Time slot   1
	Loaded a process at input/proc/p5, PID: 1, NICENESS: -20
Time slot   2
	CPU 0: Dispatched process  1 (niceness: -20, weight: 4096.000000, vruntime: 0.000000, time_slice: 4)
Time slot   3
	Loaded a process at input/proc/p8, PID: 2, NICENESS: -20
Time slot   4
Time slot   5
	Loaded a process at input/proc/p1, PID: 3, NICENESS: 10
Time slot   6
	CPU 0: Put process  1 to run queue (niceness: -20, vruntime: 0.976562)
	CPU 0: Dispatched process  2 (niceness: -20, weight: 4096.000000, vruntime: 0.000000, time_slice: 2)
Time slot   7
	Loaded a process at input/proc/p3, PID: 4, NICENESS: -5
Time slot   8
	CPU 0: Processed  2 has finished (niceness: -20, vruntime: 0.000000)
	CPU 0: Dispatched process  3 (niceness: 10, weight: 512.000000, vruntime: 0.000000, time_slice: 1)
Time slot   9
	CPU 0: Put process  3 to run queue (niceness: 10, vruntime: 1.953125)
	CPU 0: Dispatched process  4 (niceness: -5, weight: 1448.154688, vruntime: 0.000000, time_slice: 1)
Time slot  10
	CPU 0: Put process  4 to run queue (niceness: -5, vruntime: 0.690534)
	CPU 0: Dispatched process  4 (niceness: -5, weight: 1448.154688, vruntime: 0.690534, time_slice: 1)
Time slot  11
	CPU 0: Put process  4 to run queue (niceness: -5, vruntime: 1.381068)
	CPU 0: Dispatched process  1 (niceness: -20, weight: 4096.000000, vruntime: 0.976562, time_slice: 3)
Time slot  12
Time slot  13
Time slot  14
	CPU 0: Put process  1 to run queue (niceness: -20, vruntime: 1.708984)
	CPU 0: Dispatched process  4 (niceness: -5, weight: 1448.154688, vruntime: 1.381068, time_slice: 1)
Time slot  15
	CPU 0: Put process  4 to run queue (niceness: -5, vruntime: 2.071602)
	CPU 0: Dispatched process  1 (niceness: -20, weight: 4096.000000, vruntime: 1.708984, time_slice: 3)
Time slot  16
Time slot  17
Time slot  18
	CPU 0: Put process  1 to run queue (niceness: -20, vruntime: 2.441406)
	CPU 0: Dispatched process  3 (niceness: 10, weight: 512.000000, vruntime: 1.953125, time_slice: 1)
Time slot  19
	CPU 0: Put process  3 to run queue (niceness: 10, vruntime: 3.906250)
	CPU 0: Dispatched process  4 (niceness: -5, weight: 1448.154688, vruntime: 2.071602, time_slice: 1)
Time slot  20
	CPU 0: Put process  4 to run queue (niceness: -5, vruntime: 2.762136)
	CPU 0: Dispatched process  1 (niceness: -20, weight: 4096.000000, vruntime: 2.441406, time_slice: 3)
Time slot  21
Time slot  22
Time slot  23
	CPU 0: Put process  1 to run queue (niceness: -20, vruntime: 3.173828)
	CPU 0: Dispatched process  4 (niceness: -5, weight: 1448.154688, vruntime: 2.762136, time_slice: 1)
Time slot  24
	CPU 0: Put process  4 to run queue (niceness: -5, vruntime: 3.452670)
	CPU 0: Dispatched process  1 (niceness: -20, weight: 4096.000000, vruntime: 3.173828, time_slice: 3)
Time slot  25
Time slot  26
	CPU 0: Processed  1 has finished (niceness: -20, vruntime: 3.173828)
	CPU 0: Dispatched process  4 (niceness: -5, weight: 1448.154688, vruntime: 3.452670, time_slice: 3)
Time slot  27
Time slot  28
Time slot  29
	CPU 0: Put process  4 to run queue (niceness: -5, vruntime: 5.524272)
	CPU 0: Dispatched process  3 (niceness: 10, weight: 512.000000, vruntime: 3.906250, time_slice: 1)
Time slot  30
	CPU 0: Put process  3 to run queue (niceness: 10, vruntime: 5.859375)
	CPU 0: Dispatched process  4 (niceness: -5, weight: 1448.154688, vruntime: 5.524272, time_slice: 3)
Time slot  31
	CPU 0: Processed  4 has finished (niceness: -5, vruntime: 5.524272)
	CPU 0: Dispatched process  3 (niceness: 10, weight: 512.000000, vruntime: 5.859375, time_slice: 4)
Time slot  32
Time slot  33
Time slot  34
Time slot  35
	CPU 0: Put process  3 to run queue (niceness: 10, vruntime: 13.671875)
	CPU 0: Dispatched process  3 (niceness: 10, weight: 512.000000, vruntime: 13.671875, time_slice: 4)
Time slot  36
	CPU 0: Processed  3 has finished (niceness: 10, vruntime: 13.671875)
	CPU 0 stopped
