Time slot   0
ld_routine
Time slot   1
	Loaded a process at input/proc/p5, PID: 1, NICENESS: 0
	CPU 0: Dispatched process  1 (niceness: 0, weight: 1024.000000, vruntime: 0.000000, time_slice: 3)
Time slot   2
Time slot   3
	Loaded a process at input/proc/p1, PID: 2, NICENESS: -10
Time slot   4
	CPU 0: Put process  1 to run queue (niceness: 0, vruntime: 3.000000)
	CPU 0: Dispatched process  2 (niceness: -10, weight: 2048.000000, vruntime: 0.000000, time_slice: 2)
Time slot   5
Time slot   6
	CPU 0: Put process  2 to run queue (niceness: -10, vruntime: 1.000000)
	CPU 0: Dispatched process  2 (niceness: -10, weight: 2048.000000, vruntime: 1.000000, time_slice: 2)
Time slot   7
Time slot   8
	CPU 0: Put process  2 to run queue (niceness: -10, vruntime: 2.000000)
	CPU 0: Dispatched process  2 (niceness: -10, weight: 2048.000000, vruntime: 2.000000, time_slice: 2)
Time slot   9
Time slot  10
	CPU 0: Put process  2 to run queue (niceness: -10, vruntime: 3.000000)
	CPU 0: Dispatched process  1 (niceness: 0, weight: 1024.000000, vruntime: 3.000000, time_slice: 2)
Time slot  11
Time slot  12
	CPU 0: Put process  1 to run queue (niceness: 0, vruntime: 5.000000)
	CPU 0: Dispatched process  2 (niceness: -10, weight: 2048.000000, vruntime: 3.000000, time_slice: 2)
Time slot  13
Time slot  14
	CPU 0: Processed  2 has finished (niceness: -10, vruntime: 3.000000)
	CPU 0: Dispatched process  1 (niceness: 0, weight: 1024.000000, vruntime: 5.000000, time_slice: 3)
Time slot  15
Time slot  16
Time slot  17
	CPU 0: Put process  1 to run queue (niceness: 0, vruntime: 8.000000)
	CPU 0: Dispatched process  1 (niceness: 0, weight: 1024.000000, vruntime: 8.000000, time_slice: 3)
Time slot  18
Time slot  19
Time slot  20
	CPU 0: Put process  1 to run queue (niceness: 0, vruntime: 11.000000)
	CPU 0: Dispatched process  1 (niceness: 0, weight: 1024.000000, vruntime: 11.000000, time_slice: 3)
Time slot  21
Time slot  22
Time slot  23
	CPU 0: Put process  1 to run queue (niceness: 0, vruntime: 14.000000)
	CPU 0: Dispatched process  1 (niceness: 0, weight: 1024.000000, vruntime: 14.000000, time_slice: 3)
Time slot  24
	CPU 0: Processed  1 has finished (niceness: 0, vruntime: 14.000000)
	CPU 0 stopped
